# 構文エラーと例外

> エラーの種類:
    * 「構文エラー(syntax error)」:
            スクリプト実行前に構文解析され、
            構文(文法)として誤っている場合起こるエラー
    * 「例外(exception)」:
            構文(文法)として正しくても実行中に発生するエラー

> ここでは想定内の例外を捕捉し対応する例外処理ではなく、
  想定外のエラー・例外の原因の確認方法について説明する。

# エラーメッセージ(スタックトレース)の内容

## 構文エラー

> File `ファイル名`, line `行番号`
> `エラー発生個所のスクリプト内容`
>        ^ <- エラー発生個所
> `エラーの種類`: `エラーの名前`

```python
print(1)
if True
    print(2)
print(3)
# -> File "test.py", line 2
# -> if True
# ->        ^
# -> SyntaxError: invalid syntax
```

## 例外

> Traceback (most recent call last): -> 「直近の呼び出しは最後に記載」の意味
>   File `ファイルパス`, line `行番号`, in <module> <- エラー箇所を含む関数を呼び出した位置
>     a() <- 上記で示した位置にある関数呼び出し部分
>   File `ファイルパス`, line `行番号`, in a <- 上記で呼び出された関数内の、エラー箇所を含む関数を呼び出した位置
>     b() <- 上記で示した位置にある関数呼び出し部分
>   File `ファイルパス`, line `行番号`, in b <- 上記で呼び出された関数内の、エラー箇所を含む関数を呼び出した位置
>     c() <- 上記で示した位置にある関数呼び出し部分
>   File `ファイルパス`, line `行番号`, in c <- エラー発生個所
>     char.format('hello')  <- エラー発生個所のスクリプト内容
> `エラーの種類`: `エラーの説明`

```python
def a():
    """b関数を呼び出す"""
    b()

def b():
    """c関数を呼び出す"""
    c()

def c():
    """例外が発生する"""
    char = None
    char.format('hello')  # ここで例外発生

a()

# Traceback (most recent call last):
#   File "D:/Documents/Projects/Python Learning/Test.py", line 15, in <module>
#     a()
#   File "D:/Documents/Projects/Python Learning/Test.py", line 3, in a
#     b()
#   File "D:/Documents/Projects/Python Learning/Test.py", line 7, in b
#     c()
#   File "D:/Documents/Projects/Python Learning/Test.py", line 12, in c
#     char.format('hello')  # ここで例外発生
# AttributeError: 'NoneType' object has no attribute 'format'
```

# インポートに関するエラー

## モジュールが見つからない

`ModuleNotFoundError`

```python
try:
    import mathmatics
except ModuleNotFoundError as e:
    print(e)  # -> No module named 'mathmatics'
```

## モジュールのオブジェクトが見つからない

`ImportError`

> 大文字小文字も区別される

```python
try:
    from math import COS
except ImportError as e:
    print(e)  # -> cannot import name 'COS' from 'math' (unknown location)
```

# 型や値、名前に関するエラー

## オブジェクト・属性の名前が見つからない

`AttributeError`

> <オブジェクト>.<識別子>のようにメソッドなどを呼び出す際に、
  オブジェクトや識別子(属性やメソッド)の名前、
  オブジェクトの型を間違えている場合に発生する。
> 大文字小文字も区別される。

```python
import math

"識別子の名前を間違えている"
try:
    print(math.PI)
except AttributeError as e:
    print(e)  # -> module 'math' has no attribute 'PI'

"オブジェクトの型が想定と異なっている"
try:
    l = 100
    l.append(200)
except AttributeError as e:
    print(e)  # -> 'int' object has no attribute 'append'
```

## 不適切な型に対して処理が行われた

`TypeError`

> 異なる型のオブジェクトを+演算子で加算しようとした場合や、
  文字列や数値を浮動小数点型に変換する組み込み関数float()に
  そのほかの型のオブジェクトを渡した場合など。

```python
try:
    n = '100'
    print(n + 200)
except TypeError as e:
    print(e)  # -> can only concatenate str (not "int") to str

try:
    print(float(['1.23E-3']))
except TypeError as e:
    print(e)  # -> float() argument must be a string or a number, not 'list'
```

## 型は合っているが値が適切でない

`ValueError`

```python
try:
    print(float('float number'))
except ValueError as e:
    print(e)  # -> could not convert string to float: 'float number'
```

## 0で割り算が行われた

`ZeroDivisionError`

```python
try:
    print(100 / 0)
except ZeroDivisionError as e:
    print(e)  # -> division by zero

try:
    print(100 // 0)
except ZeroDivisionError as e:
    print(e)  # -> integer division or modulo by zero

try:
    print(100 % 0)
except ZeroDivisionError as e:
    print(e)  # -> integer division or modulo by zero
```

## 名前が見つからない

`NameError`

> 大文字小文字も区別される

```python
try:
    my_number = 100
    print(My_Number)
except NameError as e:
    print(e)  # -> name 'My_Number' is not defined
```

# インデックスやキーに関するエラー

## 範囲外のインデックスを指定した

`IndexError`

> リストやタプルなどのシーケンスオブジェクトに格納された値を
  インデックスで取得する際に、
  範囲外の位置(要素数を超えたインデックス値)を指定してしまった

```python
try:
    l = [0, 1, 2]
    print(l[100])
except IndexError as e:
    print(e)  # -> list index out of range
```

## 存在しないキーを指定した

`KeyError`

> 辞書の値をキーを指定して取得する際に、
  存在しないキーを指定してしまった

```python
try:
    d = {'a': 1, 'b': 2, 'c': 3}
    print(d['x'])
except KeyError as e:
    print(e)  # -> 'x'
```

# ファイルやディレクトリに関するエラー

## 指定したファイルが見つからない

`FileNotFoundError`

> open()でファイルを読み込む際などに
  指定したファイルが見つからない

```python
try:
    with open('not_exist_file.txt') as f:
        print(f.read())
except FileNotFoundError as e:
    print(e)  # -> [Errno 2] No such file or directory: 'not_exist_file.txt'
```

## 既存のファイルやフォルダを作成しようとした

`FileExistsError`

```python
import os

dir_path = r'C:\Users\KIYO\Desktop\test'
if not os.path.exists(r'C:\Users\KIYO\Desktop\test'):
    os.mkdir(dir_path)
    try:
        os.mkdir(dir_path)
    except FileExistsError as e:
        print(e)  # -> [WinError 183] 既に存在するファイルを作成することはできません。: 'C:\\Users\\KIYO\\Desktop\\test'
    os.rmdir(dir_path)
```

# リンク

[nkmk note](https://note.nkmk.me/python-error-message/)
[YoheiM .NET](https://www.yoheim.net/blog.php?q=20190601)
[Snow Tree in June](https://snowtree-injune.com/2018/09/14/exception/)
