# 例外処理の基本

> 例外処理の構文(try文)
    try: ⇒ 「try節: 必須」
        * 例外が想定されるコード
    except <例外型>: ⇒ 「except節: 複数列挙可能で一つは必須」
        * `try節`で発生した例外が、
          上記の例外型に当てはまる時に実行される処理
    except <例外型> as <変数名>:
        * `try節`で発生した例外が、
          上記の例外型に当てはまる時に実行される処理
        * 変数には発生した例外のインスタンスが入る
    except Exception:
        * `try節`で上記以外の例外型が発生した時に実行される処理
    else: ⇒ 「else節: 省略可能」
        * `try節`で例外が発生しなかった時に実行される処理
    finally: ⇒ 「finally節: 省略可能」
        * 例外発生有無にかかわらず実行される処理

> `try節`で例外が発生した時点で`try節`の中のそれ以降の処理はスキップされる。

> Exceptionクラス:
    * 構文エラーの種類である`SyntaxError`や、
      例外型である`ZeroDivisionError`などは、
      ただのエラーの名称ではなく一種のクラス。
    * クラスは「元となるクラス」の機能を継承(拡張)して、
      新しいクラスを作ることができます。
    * `ZeroDivisionError`のようなエラーに関するクラスは全て
      `Exception`クラスを継承(拡張)してできたクラス。

# try文の実行順序

## 「try節」と「except節」だけの例

```python
def div(x):
    try:
        print(f'10 / {str(x)} = {10 / x}')
        print('try節終了')
    except TypeError:
        print('TypeError')

    print('プログラム終了')

"=== 1. try節で例外が生じなかった場合 ==="
div(2)
# -> 10 / 2 = 5.0
# -> try節終了
# -> プログラム終了
"except節は実行されない"

"=== 2. try節で例外例外発生→except節で指定する例外と一致 ==="
div('2')
# -> TypeError
# -> プログラム終了
"""
try節の中で例外が発生しました。
そこで、例外が発生した行でコードの実行を中断し 次の節に実行を移します。
Try節で発生したエラーが、except節で指定したTypeErrorと一致するので、
except文が実行されます。
想定内の例外をexcept文で適切に処理したので、プログラムは終了せず、
最後の行のprint(‘プログラムの終了’)が実行されました。
"""

"=== 3. try節で例外発生→except節で指定する例外と一致しない ==="
div(0)
# ZeroDivisionError: division by zero
"""
try節で例外が発生し、try節のコードの実行を中断。
その後、次の節に実行が移るが、
この例外はexcept節で指定される例外ではありません。
想定外の例外なので、プログラムは例外を送出し、実行を停止します。
したがって、最後の行のprint(‘プログラムの終了’)は実行されません。
"""
```

## 「else節」、「finally節」を追加した例

```python
def div(x):
    try:
        print(f'10 / {str(x)} = {10 / x}')
        print('try節終了')
    except TypeError:
        print('TypeError')
    else:
        print('else節の実行')
    finally:
        print('finally節の実行')

    print('プログラム終了')

"=== 1. try節で例外が生じなかった場合 ==="
div(2)
# -> 10 / 2 = 5.0
# -> try節終了
# -> else節の実行
# -> finally節の実行
# -> プログラム終了
"""
try節で例外が発生しなかったため、try節のコードはすべて実行されます。
except節は例外が生じなかったので、実行されません。
else節は、例外が生じなかった場合に実行される節なので、実行します。
finally節は、必ず実行する節なので、実行します。
例外が生じなかったため、最後の行のprint文は実行されます。
"""

"=== 2. try節で例外例外発生→except節で指定する例外と一致 ==="
div('2')
# -> TypeError
# -> finally節の実行
# -> プログラム終了
"""
try節で例外が発生したため、try節のコードは中断し、次の節に移ります。
except節で指定した例外だったため、except節を実行します。
else節は、例外が生じなかった場合に実行される節なので、実行しません。
finally節は、必ず実行する節なので、実行します。
想定内の例外だったのでプログラムは停止せず、最後の行のprint文は実行されます。
"""

"=== 3. try節で例外発生→except節で指定する例外と一致しない ==="
div(0)
# -> finally節の実行
# ZeroDivisionError: division by zero
"""
try節で例外が発生したため、try節のコードは中断し、次の節に移ります。
except節で指定した例外とは異なるため、except節は実行しません。
else節は、例外が生じなかった場合に実行される節なので、実行しません。
finally節は、必ず実行する節なので、実行します。
想定外の例外だったので、プログラムは例外を送出し、実行を停止します。
"""
```

# 「else節」の必要性

## 「else節」のコードは、「try節」に書いても同じか

> よくよく考えると、else節は例外が生じなかったときに実行されるのであれば、
  コードをelse節に書いても、try節に書いても実行の順序は同じはずです。
  else節って本当に必要なのでしょうか？

> ① try節で例外発生行の後に記述されたコード:
        例外が生じなかったときに実行。
  ② else節に記述されたコード:
        例外が生じなかったときに実行。

## 「else節」はこんなときに必要です

> それでは、コードAとコードBを比べてみましょう。
  コードAは、5行目の`x1 = 1 / y`で例外が生じると想定されるコード
  だとします。
  一方、6行目の`x2 = 2 / z`は、
  コードを作ったときには例外が生じるとは思っていなかったとします。
> 例外とは、そもそも、思ってもいなかった例外が生じたときには、
  プログラムを停止すべきものです。
  しかし、コードAでは、6行目で想定外の例外が生じても、
  except節で適切に処理がなされ、プログラムは続行されてしまいます。
  想定外の例外が原因で更に大きなエラーを生じてしまう可能性があります。

```python
# === コードA ===
y = 1
z = 0
try:
    x1 = 1 / y  # 例外が生じる可能性があると考えているコード
    x2 = 2 / z  # 想定外の例外
except ZeroDivisionError:
    print('分母がゼロ')
print('プログラムの終了')

"""
一方、コードBのようにelse節に「x2 = 2 / z」を記述すると明快です。
例外を想定していない「x2 = 2 / z」で例外が発生すると、
プログラムは例外を送出して停止します。
"""

# === コードB ===
y = 1
z = 0
try:
    x1 = 1 / y  # 例外が生じる可能性があると考えているコード
except ZeroDivisionError:
    print('分母がゼロ')
else:
    x2 = 2 / z  # 想定外の例外
print('プログラムの終了')

"""
このように、else節を使用することで、
例外処理の対象を明確にし、
思わぬエラーが生じたときの対応を楽にすることができます。
"""
```

# 例外処理で例外の情報を出力

## 「as」変数を使う

> 「except <例外型> as <変数名>:」 とすることで、
  指定した例外型のインスタンスを変数に格納して
  あとで参照することができる。
> 例外インスタンスには例外発生時に出力される
  エラーメッセージなどが格納されているので、
  それを出力することでエラーの内容を確認できる。

```python
try:
    x = 10 / 0
except ZeroDivisionError as e:
    "変数eにはZeroDivisionErrorクラスのインスタンスが入る"
    print(type(e))  # -> <class 'ZeroDivisionError'>
    "例外インスタンを参照すると、例外の説明を返す"
    print(e)  # -> division by zero
    "<例外インスタンス>.argsは例外の説明を要素に持つタプル"
    print(e.args)  # -> ('division by zero',)
    print(e.args[0])  # -> division by zero
```

## 「sys.exc_info()」を使う

> pythonの標準ライブラリーのsysモジュールのsys.exc_info()関数
  を用いることで、同様のことができます。
> sys.exc_info()を用いる場合には、
  except節で例外型を指定しない場合でも使用できます。

```python
import sys

try:
    x = 10 / 0
except:  # Exceptionは省略して、「except:」だけでも可能
    print(sys.exc_info())
    # -> (<class 'ZeroDivisionError'>, ZeroDivisionError('division by zero'), <traceback object at 0x000002705A734808>)
    "例外型"
    print(sys.exc_info()[0])  # -> <class 'ZeroDivisionError'>
    "例外の説明"
    print(sys.exc_info()[1])  # -> division by zero
    "不明"
    print(sys.exc_info()[2])  # -> <traceback object at 0x000002705A734808>
```

## すべての例外をキャッチ

> 基本的には想定される例外型を`except節`に指定すべきだが、
  特定の例外を指定せずにすべての例外をキャッチすることも可能。

### ワイルドカードのexcept節(bare except)

> `except節`から例外型を省略するとすべての例外をキャッチできる。
> 複数の`except節`がある場合は例外型を省略できるのは最後の`except節`のみ。

> 例外型を省略した書き方は
  「ワイルドカードのexcept節」や「bare except」などと呼ばれる。
> 最後の`except節`では例外名を省いて、ワイルドカードにすることができます。
> ワイルドカードの`except節`は非常に注意して使ってください。
  というのは、ワイルドカードは通常のプログラムエラーを
  たやすく隠してしまうからです！

```python
"""この方法では例外オブジェクトを取得できない。"""
def divide_wildcard(a, b):
    try:
        print(a / b)
    except:
        print('Error')

divide_wildcard(1, 0)  # -> Error
divide_wildcard('a', 'b')  # -> Error
```

### 基底クラス「Exception」

> システム終了以外のすべての組み込み例外の基底クラスである`Exception`
  を使う方法もある。
> この方法では例外オブジェクトを取得できる。

> `as`を用いた変数への情報渡しは、
  例外型を指定しないタイプの「except節」`except:`では使用できません。
  そこで同様のことがしたい場合には、例外の種類の指定を`Exception`にします。
  Exceptionクラスは、全ての例外クラスの元になるクラスですので、
  例外の種類を指定しない「except:」と同様に、
  全ての例外に対してexcept節のコードを実行させることができます。

```python
def divide_exception(a, b):
    try:
        print(a / b)
    except Exception as e:
        print(e)

divide_exception(1, 0)  # -> division by zero
divide_exception('a', 'b')  # -> unsupported operand type(s) for /: 'str' and 'str'
```

> なお、想定していない例外までキャッチしてしまうのはバグの温床になるので、
  繰り返しになるが、`except節`には可能な限り
  想定される例外型を指定したほうがいい。

# 例外を送出するraise

> 例外を意図的に発生させたいときに使うのが`raise`です。
  raiseでは、以下の3つの書式を覚えましょう。

## 書式1

`raise <例外型>`

> `raise`の後に例外型を指定することにより、
  その例外を意図的に発生させることができます。
  コード14は、「x  = 10 / 0」とすることで、ZeroDivisionErrorを発生させていますが、コード15では、raise ZeroDivisionErrorによりZeroDivisionErrorを発生させています。

```python
# コードA
try:
    x = 10 / 0
except ZeroDivisionError as e:
    print('e.args:', e.args)  # -> e.args: ('division by zero',)
    print('e:', e)  # -> e: division by zero

# コードB
try:
    raise ZeroDivisionError 
except ZeroDivisionError as e:
    print('e.args:', e.args)  # -> e.args: ()
    print('e:', e)  # -> e:

"""コードA・Bの違いは、asを用いて変数eにエラーの情報を渡しても、
コードBでは、情報がなにも出力されない所です。"""
```

## 書式2

`raise <例外型>（<例外の説明>）`

> `raise`で発生させたい例外型の後の()のなかに
  <例外の説明>を文字列型で記入します。

```python
try:
    raise ZeroDivisionError('ゼロによる除算') 
except ZeroDivisionError as e:
    print('e.args', e.args)  # -> e.args ('ゼロによる除算',)
    print('e:', e)  # -> e: ゼロによる除算
```

> 2つ以上の<例外の説明>を登録することができる。

```python
import sys

try:
    raise ZeroDivisionError('ゼロによる除算','2つめの情報') 
except ZeroDivisionError as e:
    print('e:',e)  # -> e: ('ゼロによる除算', '2つめの情報')
    print('e.args',e.args)  # -> e.args ('ゼロによる除算', '2つめの情報')
    print('e.args[0]:',e.args[0])  # -> e.args[0]: ゼロによる除算
    print('e.args[1]:',e.args[1])  # -> e.args[1]: 2つめの情報
    print(sys.exc_info())  # -> (<class 'ZeroDivisionError'>, ZeroDivisionError('ゼロによる除算', '2つめの情報'), <traceback object at 0x00000230F66F5388>)
```

## 書式3

> except節の中で引数のない`raise`を用いると、
  try文の中で発生した例外が再送出されます。
  次のコードでは2行目で`ZeroDivisionError`が送出されますが、
  try節の中なので例外の内容は出力されず、プログラムも停止しません。
  次にtry節からexcept節に実行が移りますが、
  5行目の'raise'により、`ZeroDivisionError`が再送出され、
  スタックトレースの出力後、プログラムは実行を停止します。
  出力は「ZeroDivisionError:ゼロによる除算」となっています。

```python
try:
    raise ZeroDivisionError('ゼロによる除算') 
except ZeroDivisionError as e:
    print('e:',e)  # -> e: ゼロによる除算
    raise
# Traceback (most recent call last):
#     ...
#     raise ZeroDivisionError('ゼロによる除算')
# ZeroDivisionError: ゼロによる除算
```

## 「raise」を使った例

> x + x / aの結果を返す関数xxx()において、
  a = 0の時にはもちろん例外が発生しますが、
  aの絶対値が0.1よりも小さいときにも、
  例外が発生するようにしてみました。

```python
def xxx(x, a):
    try:
        y = x + x / a
        if -0.1 < a < 0.1 and a != 0:
            raise ZeroDivisionError('aの絶対値 < 0.1')
    except ZeroDivisionError as e:
        print('warning:関数xxx()')
        raise
    else:
        return y

#以下、関数の実行
try:
    y = xxx(1, 0)
except ZeroDivisionError as e:
    print(e.args[0])
else:
    print('x + x / a =',y)
# -> warning:関数xxx()
# -> division by zero

try:
    y = xxx(1, 0.01)
except ZeroDivisionError as e:
    print(e.args[0])
else:
    print('x + x / a =',y)
# -> warning:関数xxx()
# -> aの絶対値 < 0.1

try:
    y = xxx(1, 0.1)
except ZeroDivisionError as e:
    print(e.args[0])
else:
    print('x + x / a =',y)
# -> x + x / a = 11.0
```

# 複数の例外をキャッチ

> 除算を行いZeroDivisionErrorをキャッチする以下の関数を定義する場合。

```python
def divide(a, b):
    try:
        print(a / b)
    except ZeroDivisionError as e:
        print(e)

"""ZeroDivisionErrorはキャッチできるが、
それ以外の例外はキャッチできず処理が途中終了する。"""

divide(1, 0)
# -> division by zero
divide('a', 'b')
# TypeError: unsupported operand type(s) for /: 'str' and 'str'
```

## 複数の例外に異なる処理を実行

> `except節`は複数指定することができる。
> 複数の例外に対してそれぞれ異なる処理を記述可能。
> 複数の`except節`に該当するときには、
  一番最初の`except節`のみが実行される。

```python
def divide_each(a, b):
    try:
        print(a / b)
    except ZeroDivisionError as e:
        print(e)
    except TypeError as e:
        print(e)

divide_each(1, 0)
# -> division by zero
divide_each('a', 'b')
# -> unsupported operand type(s) for /: 'str' and 'str'
```

## 複数の例外に同じ処理を実行

> 一つの`except節`に複数の例外型をタプルで指定することもできる。
> 変数に格納される例外オブジェクトの中身はそれぞれ異なるので、
  エラーメッセージを出力してエラーの内容を確認するだけであれば
  これで問題ない。

```python
def divide_same(a, b):
    try:
        print(a / b)
    except (ZeroDivisionError, TypeError) as e:
        print(e)

divide_same(1, 0)  # -> division by zero
divide_same('a', 'b')  # -> unsupported operand type(s) for /: 'str' and 'str'
```

```python
def divide_else_finally(a, b):
    try:
        print(a / b)
    except ZeroDivisionError as e:
        print(e)
    else:
        print('finish(no error)')
    finally:
        print('all finish')

divide_else_finally(1, 2)
# -> 0.5
# -> finish(no error)
# -> all finish
divide_else_finally(1, 0)
# -> division by zero
# -> all finish
```

# 例外を無視

> 例外をキャッチしても特に何も処理を行わずにスルーしたい場合は
> `pass文`を使う。

```python
def divide_pass(a, b):
    try:
        print(a / b)
    except ZeroDivisionError:
        pass

divide_pass(1, 0)
```

# ユーザー定義例外

> ユーザー定義の例外を作成するには、`Exception`クラスを利用します。
  ここまでに`Exception`クラスが、
  他の例外のクラスの元になるような存在であることを説明しましたが、
  ユーザー定義例外は`Exception`クラスを継承(拡張)することによって作成します。
  クラスの継承は、`class <クラス名>(<元になるクラス>)`という書式で行います。

> 1行目で定義されたクラス`A_error`は
  `Exception`クラスを継承したユーザー定義の例外クラスです。
  2行目の`pass`は、何もしないことを明示する命令です。
  `class`を宣言する2行目の命令文のあとに何も書かないとエラーになるので、
  体裁を整えるためだけに記述されています。
  同様にクラス`B_error`は`A_error`を継承したユーザー定義の例外クラスです。
> 7行目以降は、ユーザー定義の例外クラスを`try`文で使用した例です。
  ここで、注目すべき点は、`Exception`クラスや、
  `A_error`クラスを継承した`B_error`クラスは、
  `except`節で指定する例外の種類が`B_error`のときだけではなく、
  `A_error`のときも、`Exception`のときも実行される点です。
  発生した例外のクラスの名称だけではなく、
  元になる親のクラスの名称でも`except`節が実行されるのです。
> なお、例外の情報を出力したい場合には、()の中に、
  例外の情報を記述します。

```python
class A_error(Exception):
    pass

class B_error(A_error):
    pass

try:
    raise B_error
except B_error:
    print('例外B_errorが発生しました。')
# -> 例外B_errorが発生しました。

try:
    raise B_error
except A_error:
    print('例外A_errorが発生しました。')
# -> 例外A_errorが発生しました。

try:
    raise B_error
except Exception:
    print('例外Exceptionが発生しました。')
# -> 例外Exceptionが発生しました。

try:
    raise B_error('例外の情報1','例外の情報2')
except B_error as e:
    print(e)  # -> ('例外の情報1', '例外の情報2')
    print(e.args)  # -> ('例外の情報1', '例外の情報2')
    print(e.args[0])  # -> 例外の情報1
    print(e.args[1])  # -> 例外の情報2
```

> 次のコードは8行目のraiseで例外を再送出し、
  プログラムを停止させた場合の例です。
  「x = 10 / 0」などの出力「ZeroDivisionError: division by zero」と
  出力の「A_error: 例外の情報」を比べてみてください。
  「ZeroDivisionError:」 に相当する部分がユーザー定義例外の「A_error: 」
  となっており、「division by zero」に相当する部分が
  「例外の情報」になっています。

```python
class A_error(Exception):
    pass

try:
    raise A_error('例外の情報')
except A_error as e:
    raise
# Traceback (most recent call last):
# ...
#     raise A_error('例外の情報')
# A_error: 例外の情報
```

[Snow Tree in June](https://snowtree-injune.com/2018/09/14/exception/#toc30)
[note.nkmk.me](https://note.nkmk.me/python-try-except-else-finally/)
